function getCheese() {
    return new Promise((resolve, reject) => {
        setTimeout(() => {
            const cheese = "üßÄ";
            resolve(cheese);
        }, 2000);
    });
}

function makeDough(cheese) {
    return new Promise((resolve, reject) => {
        setTimeout(() => {
            const dough = cheese + "üç©";
            resolve(dough);
            // reject('bad cheese'); /* reject promise example */
        }, 2000);
    });
}

function bakePizza(dough) {
    return new Promise((resolve, reject) => {
        setTimeout(() => {
            const pizza = dough + "üçï";
            resolve(pizza);
        }, 2000);
    });
}


async function orderPizza() {
    try {
        const cheese = await getCheese();
        console.log("here is the cheese", cheese);

        const dough = await makeDough(cheese);
        console.log("here is the dough", dough);

        const pizza = await bakePizza(dough);
        console.log("here is pizza", pizza);
    }
    catch (err) {
        console.log("error occured due to", err);
    }
    console.log("Process Ended");
}

orderPizza();


/* best practice for use promise is in try - catch block otherwise use then() and catch() syntax */